Workbook

Sheet Results
A1: Model | C1: Best Model | K1: TP (CS) | L1: FN | M1: FP | N1: TN (VD) | O1: Confusion Matrix | P1: Final Model | X1: TP (CS) | Y1: FN | Z1: FP | AA1: TN (VD) | AB1: Confusion Matrix
C2: ROC AUC | D2: Recall | E2: Balanced Accuracy | F2: F1-score | G2: PPV | H2: Matthews corrcoef | I2: Specificity | J2: NPV | P2: ROC AUC | Q2: Recall | R2: Balanced Accuracy | S2: F1-score | T2: PPV | U2: Matthews corrcoef | V2: Specificity | W2: NPV
A3: Multimodal Model 1 (MM1) | B3: sem seed | C3: 0.774 | D3: 0.745 | E3: 0.682 | F3: 0.74 | G3: 0.738 | H3: 0.378 | I3: 0.842 | J3: 0.803 | K3: 42.67 | L3: 39 | M3: 29.67 | N3: 158 | P3: 0.762 | Q3: 0.725 | R3: 0.671 | S3: 0.724 | T3: 0.725 | U3: 0.347 | V3: 0.808 | W3: 0.8 | X3: 43 | Y3: 38 | Z3: 36 | AA3: 151
A6: MM1 Bárbara (FTTransformer + Swin Transformer) | B6: avg of 10 runs with 10 different seeds | C6: 0.76583333 | D6: 0.73263333 | E6: 0.6407 | F6: 0.7055 | G6: 0.73836667 | H6: 0.3079 | I6: 0.87483333 | J6: 0.7774 | K6: 33.2 | L6: 48.466667 | M6: 23.533333 | N6: 164.13333 | P6: 0.7614 | Q6: 0.72793333 | R6: 0.6728 | S6: 0.72456667 | T6: 0.72746667 | U6: 0.3511 | V6: 0.81276667 | W6: 0.80263333 | X6: 43.533333 | Y6: 38.433333 | Z6: 35.166667 | AA6: 152.53333
B8: std of 10 runs with 10 different seeds | C8: 0.014929671 | D8: 0.012122268 | E8: 0.024986638 | F8: 0.024091518 | G8: 0.018947914 | H8: 0.052161679 | I8: 0.02833061 | J8: 0.015350071 | K8: 5.8377232 | L8: 5.8377232 | M8: 5.3222106 | N8: 5.3222106 | P8: 0.0084060531 | Q8: 0.0061016088 | R8: 0.016332351 | S8: 0.0070044959 | T8: 0.010868689 | U8: 0.02461007 | V8: 0.026317177 | W8: 0.015543209 | X8: 4.6032731 | Y8: 4.7843624 | Z8: 5.0289287 | AA8: 4.9521164
A11: FTTransformer + FetalCLIP | B11: avg of 10 runs with 10 different seeds | C11: 0.76403333 | D11: 0.733 | E11: 0.64916667 | F11: 0.7147 | G11: 0.72696667 | H11: 0.32443333 | I11: 0.8624 | J11: 0.78263333 | K11: 35.6 | L11: 46.066667 | M11: 25.833333 | N11: 161.83333 | P11: 0.7554 | Q11: 0.72256667 | R11: 0.6582 | S11: 0.71736667 | T11: 0.71826667 | U11: 0.3291 | V11: 0.8216 | W11: 0.79006667 | X11: 40.433333 | Y11: 41.233333 | Z11: 33.466667 | AA11: 154.2
B13: std of 10 runs with 10 different seeds | C13: 0.011171447 | D13: 0.011861339 | E13: 0.024292584 | F13: 0.022704462 | G13: 0.010916575 | H13: 0.048062986 | I13: 0.028257983 | J13: 0.015087768 | K13: 5.693401 | L13: 5.693401 | M13: 5.3292809 | N13: 5.3292809 | P13: 0.0089398539 | Q13: 0.0087911993 | R13: 0.015197628 | S13: 0.0077578316 | T13: 0.0098992455 | U13: 0.023181011 | V13: 0.030189443 | W13: 0.013341479 | X13: 4.5434799 | Y13: 4.5434799 | Z13: 5.672546 | AA13: 5.672546
A16: FTTransformer + MedMamba-s (pretrained) | B16: avg of 10 runs with 10 different seeds | C16: 0.72016667 | D16: 0.7109 | E16: 0.60486667 | F16: 0.6725 | G16: 0.71136667 | H16: 0.2323 | I16: 0.87476667 | J16: 0.75783333 | K16: 27.333333 | L16: 54.333333 | M16: 23.533333 | N16: 164.13333 | P16: 0.7074 | Q16: 0.6913 | R16: 0.61433333 | S16: 0.67576667 | T16: 0.68883333 | U16: 0.24663333 | V16: 0.80993333 | W16: 0.76786667 | X16: 34.2 | Y16: 47.466667 | Z16: 35.666667 | AA16: 152
B18: std of 10 runs with 10 different seeds | C18: 0.016953276 | D18: 0.015327736 | E18: 0.024172834 | F18: 0.019899283 | G18: 0.029040393 | H18: 0.045083585 | I18: 0.040150965 | J18: 0.016502338 | K18: 6.2360956 | L18: 6.2360956 | M18: 7.5542483 | N18: 7.5542483 | P18: 0.022719872 | Q18: 0.029271167 | R18: 0.025593691 | S18: 0.026675485 | T18: 0.017488091 | U18: 0.045036734 | V18: 0.072750682 | W18: 0.019595414 | X18: 7.9925892 | Y18: 7.9925892 | Z18: 13.64904 | AA18: 13.64904
A21: FTTransformer + MedVitV2 - b (no pretrained) | B21: avg of 10 runs with 10 different seeds | C21: 0.74976667 | D21: 0.7395 | E21: 0.64993333 | F21: 0.7159 | G21: 0.73993333 | H21: 0.32523333 | I21: 0.878 | J21: 0.7817 | K21: 34.433333 | L21: 47.233333 | M21: 22.866667 | N21: 164.76667 | P21: 0.75836667 | Q21: 0.72756667 | R21: 0.67043333 | S21: 0.723 | T21: 0.72923333 | U21: 0.35193333 | V21: 0.81576667 | W21: 0.80096667 | X21: 42.9 | Y21: 38.766667 | Z21: 34.6 | AA21: 153.06667
B23: std of 10 runs with 10 different seeds | C23: 0.024987923 | D23: 0.010483673 | E23: 0.020985474 | F23: 0.024241099 | G23: 0.015279939 | H23: 0.051870696 | I23: 0.016860356 | J23: 0.010230009 | K23: 4.3206367 | L23: 4.3206367 | M23: 3.1158694 | N23: 3.1546556 | O23: #DIV/0! | P23: 0.011257316 | Q23: 0.020781669 | R23: 0.020250926 | S23: 0.017566101 | T23: 0.012649159 | U23: 0.031969044 | V23: 0.056303422 | W23: 0.019413913 | X23: 6.6240303 | Y23: 6.6240303 | Z23: 10.579272 | AA23: 10.579272
A26: FTTransformer + MedVitV2 - b (pretrained) | B26: avg of 10 runs with 10 different seeds | C26: 0.7478 | D26: 0.72326667 | E26: 0.64246667 | F26: 0.7018 | G26: 0.7255 | H26: 0.31366667 | I26: 0.8481 | J26: 0.78246667 | K26: 35.666667 | L26: 46 | M26: 28.466667 | N26: 159.13333 | P26: 0.74883333 | Q26: 0.7201 | R26: 0.6587 | S26: 0.71343333 | T26: 0.72236667 | U26: 0.3316 | V26: 0.8145 | W26: 0.793 | X26: 41.066667 | Y26: 40.6 | Z26: 34.8 | AA26: 152.86667
B28: std of 10 runs with 10 different seeds | C28: 0.020588382 | D28: 0.01758282 | E28: 0.026614857 | F28: 0.02056018 | G28: 0.012281925 | H28: 0.036068522 | I28: 0.056460639 | J28: 0.020408301 | K28: 8.0920629 | L28: 8.0920629 | M28: 10.648364 | N28: 10.603051 | O28: #DIV/0! | P28: 0.013950751 | Q28: 0.013637322 | R28: 0.020529683 | S28: 0.011957796 | T28: 0.0091563241 | U28: 0.021992591 | V28: 0.052395988 | W28: 0.017874736 | X28: 7.1626604 | Y28: 7.1626604 | Z28: 9.8509885 | AA28: 9.8509885
A31: FTTransformer + MedSigLiP | B31: avg of 10 runs with 10 different seeds | C31: 0.76373333 | D31: 0.73123333 | E31: 0.65403333 | F31: 0.71786667 | G31: 0.7237 | H31: 0.33346667 | I31: 0.85056667 | J31: 0.78633333 | K31: 37.366667 | L31: 44.3 | M31: 28.066667 | N31: 159.6 | P31: 0.74563333 | Q31: 0.71133333 | R31: 0.6613 | S31: 0.70623333 | T31: 0.72196667 | U31: 0.32853333 | V31: 0.78816667 | W31: 0.80166667 | X31: 43.666667 | Y31: 36.233333 | Z31: 41.533333 | AA31: 147.9
B33: std of 10 runs with 10 different seeds | C33: 0.011315476 | D33: 0.012198406 | E33: 0.016525032 | F33: 0.014239382 | G33: 0.0093564594 | H33: 0.026502914 | I33: 0.027798501 | J33: 0.012271014 | K33: 4.0426889 | L33: 4.0426889 | M33: 5.2255781 | N33: 5.2255781 | P33: 0.0089597247 | Q33: 0.014696938 | R33: 0.0046030183 | S33: 0.014750556 | T33: 0.0089820191 | U33: 0.014233919 | V33: 0.036195534 | W33: 0.009863513 | X33: 2.996294 | Y33: 6.1842991 | Z33: 8.4619409 | AA33: 6.7987744
A36: FTTransformer + MedSigLiP (finetuned) | B36: avg of 10 runs with 10 different seeds | C36: 0.76236667 | D36: 0.73486667 | E36: 0.63703333 | F36: 0.70486667 | G36: 0.7345 | H36: 0.30476667 | I36: 0.88616667 | J36: 0.77486667 | K36: 31.666667 | L36: 50 | M36: 21.366667 | N36: 166.3 | P36: 0.74453333 | Q36: 0.70763333 | R36: 0.6608 | S36: 0.70363333 | T36: 0.72233333 | U36: 0.328 | V36: 0.77976667 | W36: 0.80233333 | X36: 44.266667 | Y36: 37.4 | Z36: 41.333333 | AA36: 146.33333
B38: std of 10 runs with 10 different seeds | C38: 0.012160907 | D38: 0.011070147 | E38: 0.023948221 | F38: 0.023525243 | G38: 0.019479175 | H38: 0.04937862 | I38: 0.027096194 | J38: 0.014750769 | K38: 5.6240225 | L38: 5.6240225 | M38: 5.0782762 | N38: 5.0782762 | P38: 0.015802172 | Q38: 0.020604716 | R38: 0.023325501 | S38: 0.01372971 | T38: 0.01038874 | U38: 0.025168568 | V38: 0.075467768 | W38: 0.025720722 | X38: 9.4474505 | Y38: 9.4474505 | Z38: 14.15784 | AA38: 14.15784
A40: BEST SEEDS
A42: MM1 Bárbara (FTTransformer + Swin Transformer) | B42: avg best seed - 21 | C42: 0.78333333 | D42: 0.74266667 | E42: 0.68366667 | F42: 0.739 | G42: 0.737 | H42: 0.37666667 | I42: 0.833 | J42: 0.805 | K42: 43.666667 | L42: 38 | M42: 31.333333 | N42: 156.33333 | P42: 0.77066667 | Q42: 0.729 | R42: 0.681 | S42: 0.72766667 | T42: 0.73166667 | U42: 0.36233333 | V42: 0.803 | W42: 0.80933333 | X42: 45.666667 | Y42: 36 | Z42: 37 | AA42: 150.66667
B44: std best seed | C44: 0.018717194 | D44: 0.012096832 | E44: 0.023544285 | F44: 0.01473092 | G44: 0.017088007 | H44: 0.039551654 | I44: 0.013527749 | J44: 0.018083141 | K44: 4.7258156 | L44: 4.5825757 | M44: 2.5166115 | N44: 2.5166115 | P44: 0.017925773 | Q44: 0.0036055513 | R44: 0.036660606 | S44: 0.01274101 | T44: 0.020840665 | U44: 0.048880807 | V44: 0.050685304 | W44: 0.033857545 | X44: 10.066446 | Y44: 10.148892 | Z44: 9.539392 | AA44: 9.0184995
A47: FTTransformer + FetalCLIP | B47: avg best seed - 21 | C47: 0.76333333 | D47: 0.73766667 | E47: 0.68366667 | F47: 0.734 | G47: 0.73766667 | H47: 0.374 | I47: 0.821 | J47: 0.809 | K47: 44.666667 | L47: 37 | M47: 33.666667 | N47: 154 | P47: 0.742 | Q47: 0.71033333 | R47: 0.641 | S47: 0.705 | T47: 0.70133333 | U47: 0.292 | V47: 0.817 | W47: 0.77866667 | X47: 38 | Y47: 43.666667 | Z47: 34.333333 | AA47: 153.33333
B49: std best seed | C49: 0.033501244 | D49: 0.0049328829 | E49: 0.040377386 | F49: 0.012288206 | G49: 0.021126603 | H49: 0.051419841 | I49: 0.058557664 | J49: 0.037722672 | K49: 11.590226 | L49: 11.135529 | M49: 11.015141 | N49: 11 | P49: 0.030265492 | Q49: 0.023713569 | R49: 0.031749016 | S49: 0.024979992 | T49: 0.026102363 | U49: 0.063694584 | V49: 0.013527749 | W49: 0.017387735 | X49: 4.3588989 | Y49: 3.7859389 | Z49: 2.5166115 | AA49: 2.5166115
A52: FTTransformer + MedMamba-s (pretrained) | B52: avg best seed - 10 | C52: 0.72666667 | D52: 0.73866667 | E52: 0.64366667 | F52: 0.71233333 | G52: 0.72233333 | H52: 0.32233333 | I52: 0.88666667 | J52: 0.778 | K52: 32.666667 | L52: 49 | M52: 21.333333 | N52: 166.33333 | P52: 0.727 | Q52: 0.70166667 | R52: 0.66266667 | S52: 0.70533333 | T52: 0.712 | U52: 0.317 | V52: 0.762 | W52: 0.801 | X52: 46 | Y52: 35.666667 | Z52: 44.666667 | AA52: 143
B54: std best seed | C54: 0.065957057 | D54: 0.047014182 | E54: 0.094368074 | F54: 0.075804573 | G54: 0.07296803 | H54: 0.18142859 | I54: 0.081156228 | J54: 0.060324125 | K54: 19.857828 | L54: 20.297783 | M54: 15.30795 | N54: 15.011107 | P54: 0.051961524 | Q54: 0.023115651 | R54: 0.03453018 | S54: 0.02454248 | T54: 0.028 | U54: 0.062952363 | V54: 0.029816103 | W54: 0.027073973 | X54: 6.244998 | Y54: 6.6583281 | Z54: 5.6862407 | AA54: 5.5677644
A57: FTTransformer + MedVitV2 - b (no pretrained) | B57: avg best seed - 10 | C57: 0.771 | D57: 0.75466667 | E57: 0.677 | F57: 0.74366667 | G57: 0.74833333 | H57: 0.39166667 | I57: 0.87533333 | J57: 0.79466667 | K57: 39 | L57: 42.666667 | M57: 23.333333 | N57: 164.33333 | P57: 0.75433333 | Q57: 0.74266667 | R57: 0.68466667 | S57: 0.73766667 | T57: 0.73966667 | U57: 0.37866667 | V57: 0.83133333 | W57: 0.80933333 | X57: 44 | Y57: 37.666667 | Z57: 31.666667 | AA57: 156
B59: std best seed | C59: 0.023259407 | D59: 0.026501572 | E59: 0.021377558 | F59: 0.020008332 | G59: 0.030353473 | H59: 0.057587614 | I59: 0.061533189 | J59: 0.018448125 | K59: 6.0827625 | L59: 6.6583281 | M59: 11.590226 | N59: 11.676187 | P59: 0.045236416 | Q59: 0.023115651 | R59: 0.062740205 | S59: 0.03139002 | T59: 0.040820746 | U59: 0.095714854 | V59: 0.045621632 | W59: 0.052576928 | X59: 13.892444 | Y59: 13.576941 | Z59: 8.6216781 | AA59: 8.5440037
A62: FTTransformer + MedVitV2 - b (pretrained) | B62: avg best seed - 43 | C62: 0.76233333 | D62: 0.72666667 | E62: 0.69533333 | F62: 0.73066667 | G62: 0.738 | H62: 0.378 | I62: 0.77466667 | J62: 0.82266667 | K62: 50.333333 | L62: 31.333333 | M62: 42.333333 | N62: 145.33333 | P62: 0.73033333 | Q62: 0.72166667 | R62: 0.63433333 | S62: 0.70666667 | T62: 0.708 | U62: 0.29866667 | V62: 0.85633333 | W62: 0.77066667 | X62: 33.666667 | Y62: 48 | Z62: 27 | AA62: 160.66667
B64: std best seed | C64: 0.027592269 | D64: 0.0028867513 | E64: 0.0092915732 | F64: 0.0037859389 | G64: 0.007 | H64: 0.01473092 | I64: 0.0077674535 | J64: 0.008326664 | K64: 2.3094011 | L64: 2.081666 | M64: 1.5275252 | N64: 1.1547005 | P64: 0.045785733 | Q64: 0.01040833 | R64: 0.019756855 | S64: 0.0058594653 | T64: 0 | U64: 0.011846237 | V64: 0.056145644 | W64: 0.018009257 | X64: 7.5055535 | Y64: 8 | Z64: 10.535654 | AA64: 10.503968
A67: FTTransformer + MedSigLiP | B67: avg best seed - 10 | C67: 0.78533333 | D67: 0.75233333 | E67: 0.67833333 | F67: 0.74066667 | G67: 0.74133333 | H67: 0.37966667 | I67: 0.867 | J67: 0.799 | K67: 40 | L67: 41.666667 | M67: 25 | N67: 162.66667 | P67: 0.75633333 | Q67: 0.74266667 | R67: 0.65866667 | S67: 0.72666667 | T67: 0.732 | U67: 0.35066667 | V67: 0.872 | W67: 0.786 | X67: 36.333333 | Y67: 45.333333 | Z67: 24 | AA67: 163.66667
B69: std best seed | C69: 0.022744963 | D69: 0.036665151 | E69: 0.07366365 | F69: 0.051052261 | G69: 0.050934599 | H69: 0.12671753 | I69: 0.032140317 | J69: 0.050408333 | K69: 14.106736 | L69: 14.189198 | M69: 6.0827625 | N69: 5.7735027 | P69: 0.039803685 | Q69: 0.013503086 | R69: 0.051694616 | S69: 0.032807519 | T69: 0.02007486 | U69: 0.068391033 | V69: 0.053702886 | W69: 0.03671512 | X69: 12.503333 | Y69: 12.858201 | Z69: 10.148892 | AA69: 9.6090235
A72: FTTransformer + MedSigLiP (finetuned) | B72: avg best seed - 43 | C72: 0.77533333 | D72: 0.75233333 | E72: 0.66333333 | F72: 0.73733333 | G72: 0.738 | H72: 0.36866667 | I72: 0.88966667 | J72: 0.784 | K72: 35.666667 | L72: 46 | M72: 20.666667 | N72: 167 | P72: 0.75733333 | Q72: 0.72633333 | R72: 0.65966667 | S72: 0.71466667 | T72: 0.73033333 | U72: 0.342 | V72: 0.82933333 | W72: 0.79433333 | X72: 40 | Y72: 41.666667 | Z72: 32 | AA72: 155.66667
B74: std best seed | C74: 0.033650161 | D74: 0.03300505 | E74: 0.040153871 | F74: 0.03494758 | G74: 0.038974351 | H74: 0.09078179 | I74: 0.022501852 | J74: 0.021633308 | K74: 5.033223 | L74: 4.5825757 | M74: 4.163332 | N74: 4.3588989 | P74: 0.025540817 | Q74: 0.010066446 | R74: 0.051286775 | S74: 0.018823744 | T74: 0.0070945989 | U74: 0.042930176 | V74: 0.1039439 | W74: 0.04387862 | X74: 16.643317 | Y74: 17.009801 | Z74: 19.467922 | AA74: 19.655364

Sheet Results-comparação
A1: Model | C1: Best Model | K1: TP (CS) | L1: FN | M1: FP | N1: TN (VD) | O1: Confusion Matrix | P1: Final Model | X1: TP (CS) | Y1: FN | Z1: FP | AA1: TN (VD) | AB1: Confusion Matrix
C2: ROC AUC | D2: Recall | E2: Balanced Accuracy | F2: F1-score | G2: PPV | H2: Matthews corrcoef | I2: Specificity | J2: NPV | P2: ROC AUC | Q2: Recall | R2: Balanced Accuracy | S2: F1-score | T2: PPV | U2: Matthews corrcoef | V2: Specificity | W2: NPV
A3: Multimodal Model 1 (MM1) | B3: sem seed | C3: 0.774 | D3: 0.745 | E3: 0.682 | F3: 0.74 | G3: 0.738 | H3: 0.378 | I3: 0.842 | J3: 0.803 | K3: 42.67 | L3: 39 | M3: 29.67 | N3: 158 | P3: 0.762 | Q3: 0.725 | R3: 0.671 | S3: 0.724 | T3: 0.725 | U3: 0.347 | V3: 0.808 | W3: 0.8 | X3: 43 | Y3: 38 | Z3: 36 | AA3: 151
A6: MM1 Bárbara (FTTransformer + Swin Transformer) | B6: avg of 10 runs with 10 different seeds | C6: =Results!C6 - C3 -> -0.0081666667 | D6: =Results!D6 - D3 -> -0.012366667 | E6: =Results!E6 - E3 -> -0.0413 | F6: =Results!F6 - F3 -> -0.0345 | G6: =Results!G6 - G3 -> 0.00036666667 | H6: =Results!H6 - H3 -> -0.0701 | I6: =Results!I6 - I3 -> 0.032833333 | J6: =Results!J6 - J3 -> -0.0256 | ... N6: =Results!N6 - N3 -> 6.1333333 | P6: =Results!P6 - P3 -> -0.0006 | Q6: =Results!Q6 - Q3 -> 0.0029333333 | R6: =Results!R6 - R3 -> 0.0018 | S6: =Results!S6 - S3 -> 0.00056666667 | T6: =Results!T6 - T3 -> 0.0024666667 | U6: =Results!U6 - U3 -> 0.0041 | V6: =Results!V6 - V3 -> 0.0047666667 | W6: =Results!W6 - W3 -> 0.0026333333 | ... AA6: =Results!AA6 - AA3 -> 1.5333333
A9: FTTransformer + FetalCLIP | B9: avg of 10 runs with 10 different seeds | C9: =Results!C11 - C3 -> -0.0099666667 | D9: =Results!D11 - D3 -> -0.012 | E9: =Results!E11 - E3 -> -0.032833333 | F9: =Results!F11 - F3 -> -0.0253 | G9: =Results!G11 - G3 -> -0.011033333 | H9: =Results!H11 - H3 -> -0.053566667 | I9: =Results!I11 - I3 -> 0.0204 | J9: =Results!J11 - J3 -> -0.020366667 | ... N9: =Results!N11 - N3 -> 3.8333333 | P9: =Results!P11 - P3 -> -0.0066 | Q9: =Results!Q11 - Q3 -> -0.0024333333 | R9: =Results!R11 - R3 -> -0.0128 | S9: =Results!S11 - S3 -> -0.0066333333 | T9: =Results!T11 - T3 -> -0.0067333333 | U9: =Results!U11 - U3 -> -0.0179 | V9: =Results!V11 - V3 -> 0.0136 | W9: =Results!W11 - W3 -> -0.0099333333 | ... AA9: =Results!AA11 - AA3 -> 3.2
A12: FTTransformer + MedMamba-s (pretrained) | B12: avg of 10 runs with 10 different seeds | C12: =Results!C16 - C3 -> -0.053833333 | D12: =Results!D16 - D3 -> -0.0341 | E12: =Results!E16 - E3 -> -0.077133333 | F12: =Results!F16 - F3 -> -0.0675 | G12: =Results!G16 - G3 -> -0.026633333 | H12: =Results!H16 - H3 -> -0.1457 | I12: =Results!I16 - I3 -> 0.032766667 | J12: =Results!J16 - J3 -> -0.045166667 | ... N12: =Results!N16 - N3 -> 6.1333333 | P12: =Results!P16 - P3 -> -0.0546 | Q12: =Results!Q16 - Q3 -> -0.0337 | R12: =Results!R16 - R3 -> -0.056666667 | S12: =Results!S16 - S3 -> -0.048233333 | T12: =Results!T16 - T3 -> -0.036166667 | U12: =Results!U16 - U3 -> -0.10036667 | V12: =Results!V16 - V3 -> 0.0019333333 | W12: =Results!W16 - W3 -> -0.032133333 | ... AA12: =Results!AA16 - AA3 -> 1
A15: FTTransformer + MedVitV2 - b (no pretrained) | B15: avg of 10 runs with 10 different seeds | C15: =Results!C21 - C3 -> -0.024233333 | D15: =Results!D21 - D3 -> -0.0055 | E15: =Results!E21 - E3 -> -0.032066667 | F15: =Results!F21 - F3 -> -0.0241 | G15: =Results!G21 - G3 -> 0.0019333333 | H15: =Results!H21 - H3 -> -0.052766667 | I15: =Results!I21 - I3 -> 0.036 | J15: =Results!J21 - J3 -> -0.0213 | ... N15: =Results!N21 - N3 -> 6.7666667 | P15: =Results!P21 - P3 -> -0.0036333333 | Q15: =Results!Q21 - Q3 -> 0.0025666667 | R15: =Results!R21 - R3 -> -0.00056666667 | S15: =Results!S21 - S3 -> -0.001 | T15: =Results!T21 - T3 -> 0.0042333333 | U15: =Results!U21 - U3 -> 0.0049333333 | V15: =Results!V21 - V3 -> 0.0077666667 | W15: =Results!W21 - W3 -> 0.00096666667 | ... AB15: =Results!AB21 - AB3 -> 0
A18: FTTransformer + MedVitV2 - b (pretrained) | B18: avg of 10 runs with 10 different seeds | C18: =Results!C26 - C3 -> -0.0262 | D18: =Results!D26 - D3 -> -0.021733333 | E18: =Results!E26 - E3 -> -0.039533333 | F18: =Results!F26 - F3 -> -0.0382 | G18: =Results!G26 - G3 -> -0.0125 | H18: =Results!H26 - H3 -> -0.064333333 | I18: =Results!I26 - I3 -> 0.0061 | J18: =Results!J26 - J3 -> -0.020533333 | ... N18: =Results!N26 - N3 -> 1.1333333 | P18: =Results!P26 - P3 -> -0.013166667 | Q18: =Results!Q26 - Q3 -> -0.0049 | R18: =Results!R26 - R3 -> -0.0123 | S18: =Results!S26 - S3 -> -0.010566667 | T18: =Results!T26 - T3 -> -0.0026333333 | U18: =Results!U26 - U3 -> -0.0154 | V18: =Results!V26 - V3 -> 0.0065 | W18: =Results!W26 - W3 -> -0.007 | ... AA18: =Results!AA26 - AA3 -> 1.8666667
A21: FTTransformer + MedSigLiP | B21: avg of 10 runs with 10 different seeds | C21: =Results!C31 - C3 -> -0.010266667 | D21: =Results!D31 - D3 -> -0.013766667 | E21: =Results!E31 - E3 -> -0.027966667 | F21: =Results!F31 - F3 -> -0.022133333 | G21: =Results!G31 - G3 -> -0.0143 | H21: =Results!H31 - H3 -> -0.044533333 | I21: =Results!I31 - I3 -> 0.0085666667 | J21: =Results!J31 - J3 -> -0.016666667 | ... N21: =Results!N31 - N3 -> 1.6 | P21: =Results!P31 - P3 -> -0.016366667 | Q21: =Results!Q31 - Q3 -> -0.013666667 | R21: =Results!R31 - R3 -> -0.0097 | S21: =Results!S31 - S3 -> -0.017766667 | T21: =Results!T31 - T3 -> -0.0030333333 | U21: =Results!U31 - U3 -> -0.018466667 | V21: =Results!V31 - V3 -> -0.019833333 | W21: =Results!W31 - W3 -> 0.0016666667 | ... AB21: =Results!AB31 - AB3 -> 0
A24: FTTransformer + MedSigLiP | B24: avg of 10 runs with 10 different seeds | C24: =Results!C36 - C3 -> -0.011633333 | D24: =Results!D36 - D3 -> -0.010133333 | E24: =Results!E36 - E3 -> -0.044966667 | F24: =Results!F36 - F3 -> -0.035133333 | G24: =Results!G36 - G3 -> -0.0035 | H24: =Results!H36 - H3 -> -0.073233333 | I24: =Results!I36 - I3 -> 0.044166667 | J24: =Results!J36 - J3 -> -0.028133333 | ... N24: =Results!N36 - N3 -> 8.3 | P24: =Results!P36 - P3 -> -0.017466667 | Q24: =Results!Q36 - Q3 -> -0.017366667 | R24: =Results!R36 - R3 -> -0.0102 | S24: =Results!S36 - S3 -> -0.020366667 | T24: =Results!T36 - T3 -> -0.0026666667 | U24: =Results!U36 - U3 -> -0.019 | V24: =Results!V36 - V3 -> -0.028233333 | W24: =Results!W36 - W3 -> 0.0023333333 | ... AB24: =Results!AB36 - AB3 -> 0
A28: BEST SEEDS
A30: MM1 Bárbara (FTTransformer + Swin Transformer) | B30: avg best seed - 21 | C30: =Results!C42 - C3 -> 0.0093333333 | D30: =Results!D42 - D3 -> -0.0023333333 | E30: =Results!E42 - E3 -> 0.0016666667 | F30: =Results!F42 - F3 -> -0.001 | G30: =Results!G42 - G3 -> -0.001 | H30: =Results!H42 - H3 -> -0.0013333333 | I30: =Results!I42 - I3 -> -0.009 | J30: =Results!J42 - J3 -> 0.002 | ... N30: =Results!N42 - N3 -> -1.6666667 | P30: =Results!P42 - P3 -> 0.0086666667 | Q30: =Results!Q42 - Q3 -> 0.004 | R30: =Results!R42 - R3 -> 0.01 | S30: =Results!S42 - S3 -> 0.0036666667 | T30: =Results!T42 - T3 -> 0.0066666667 | U30: =Results!U42 - U3 -> 0.015333333 | V30: =Results!V42 - V3 -> -0.005 | W30: =Results!W42 - W3 -> 0.0093333333 | ... AA30: =Results!AA42 - AA3 -> -0.33333333
A33: FTTransformer + FetalCLIP | B33: avg best seed - 21 | C33: =Results!C47 - C3 -> -0.010666667 | D33: =Results!D47 - D3 -> -0.0073333333 | E33: =Results!E47 - E3 -> 0.0016666667 | F33: =Results!F47 - F3 -> -0.006 | G33: =Results!G47 - G3 -> -0.00033333333 | H33: =Results!H47 - H3 -> -0.004 | I33: =Results!I47 - I3 -> -0.021 | J33: =Results!J47 - J3 -> 0.006 | ... N33: =Results!N47 - N3 -> -4 | P33: =Results!P47 - P3 -> -0.02 | Q33: =Results!Q47 - Q3 -> -0.014666667 | R33: =Results!R47 - R3 -> -0.03 | S33: =Results!S47 - S3 -> -0.019 | T33: =Results!T47 - T3 -> -0.023666667 | U33: =Results!U47 - U3 -> -0.055 | V33: =Results!V47 - V3 -> 0.009 | W33: =Results!W47 - W3 -> -0.021333333 | ... AA33: =Results!AA47 - AA3 -> 2.3333333
A36: FTTransformer + MedMamba-s (pretrained) | B36: avg best seed - 10 | C36: =Results!C52 - C3 -> -0.047333333 | D36: =Results!D52 - D3 -> -0.0063333333 | E36: =Results!E52 - E3 -> -0.038333333 | F36: =Results!F52 - F3 -> -0.027666667 | G36: =Results!G52 - G3 -> -0.015666667 | H36: =Results!H52 - H3 -> -0.055666667 | I36: =Results!I52 - I3 -> 0.044666667 | J36: =Results!J52 - J3 -> -0.025 | ... N36: =Results!N52 - N3 -> 8.3333333 | P36: =Results!P52 - P3 -> -0.035 | Q36: =Results!Q52 - Q3 -> -0.023333333 | R36: =Results!R52 - R3 -> -0.0083333333 | S36: =Results!S52 - S3 -> -0.018666667 | T36: =Results!T52 - T3 -> -0.013 | U36: =Results!U52 - U3 -> -0.03 | V36: =Results!V52 - V3 -> -0.046 | W36: =Results!W52 - W3 -> 0.001 | ... AA36: =Results!AA52 - AA3 -> -8
A39: FTTransformer + MedVitV2 - b (no pretrained) | B39: avg best seed - 10 | C39: =Results!C57 - C3 -> -0.003 | D39: =Results!D57 - D3 -> 0.0096666667 | E39: =Results!E57 - E3 -> -0.005 | F39: =Results!F57 - F3 -> 0.0036666667 | G39: =Results!G57 - G3 -> 0.010333333 | H39: =Results!H57 - H3 -> 0.013666667 | I39: =Results!I57 - I3 -> 0.033333333 | J39: =Results!J57 - J3 -> -0.0083333333 | ... N39: =Results!N57 - N3 -> 6.3333333 | P39: =Results!P57 - P3 -> -0.0076666667 | Q39: =Results!Q57 - Q3 -> 0.017666667 | R39: =Results!R57 - R3 -> 0.013666667 | S39: =Results!S57 - S3 -> 0.013666667 | T39: =Results!T57 - T3 -> 0.014666667 | U39: =Results!U57 - U3 -> 0.031666667 | V39: =Results!V57 - V3 -> 0.023333333 | W39: =Results!W57 - W3 -> 0.0093333333 | ... AB39: =Results!AB57 - AB3 -> 0
A42: FTTransformer + MedVitV2 - b (pretrained) | B42: avg best seed - 43 | C42: =Results!C62 - C3 -> -0.011666667 | D42: =Results!D62 - D3 -> -0.018333333 | E42: =Results!E62 - E3 -> 0.013333333 | F42: =Results!F62 - F3 -> -0.0093333333 | G42: =Results!G62 - G3 -> 0 | H42: =Results!H62 - H3 -> 0 | I42: =Results!I62 - I3 -> -0.067333333 | J42: =Results!J62 - J3 -> 0.019666667 | ... N42: =Results!N62 - N3 -> -12.666667 | P42: =Results!P62 - P3 -> -0.031666667 | Q42: =Results!Q62 - Q3 -> -0.0033333333 | R42: =Results!R62 - R3 -> -0.036666667 | S42: =Results!S62 - S3 -> -0.017333333 | T42: =Results!T62 - T3 -> -0.017 | U42: =Results!U62 - U3 -> -0.048333333 | V42: =Results!V62 - V3 -> 0.048333333 | W42: =Results!W62 - W3 -> -0.029333333 | ... AB42: =Results!AB62 - AB3 -> 0
A45: FTTransformer + MedSigLiP | B45: avg best seed - 10 | C45: =Results!C67 - C3 -> 0.011333333 | D45: =Results!D67 - D3 -> 0.0073333333 | E45: =Results!E67 - E3 -> -0.0036666667 | F45: =Results!F67 - F3 -> 0.00066666667 | G45: =Results!G67 - G3 -> 0.0033333333 | H45: =Results!H67 - H3 -> 0.0016666667 | I45: =Results!I67 - I3 -> 0.025 | J45: =Results!J67 - J3 -> -0.004 | ... N45: =Results!N67 - N3 -> 4.6666667 | P45: =Results!P67 - P3 -> -0.0056666667 | Q45: =Results!Q67 - Q3 -> 0.017666667 | R45: =Results!R67 - R3 -> -0.012333333 | S45: =Results!S67 - S3 -> 0.0026666667 | T45: =Results!T67 - T3 -> 0.007 | U45: =Results!U67 - U3 -> 0.0036666667 | V45: =Results!V67 - V3 -> 0.064 | W45: =Results!W67 - W3 -> -0.014 | ... AB45: =Results!AB67 - AB3 -> 0
A48: FTTransformer + MedSigLiP (finetuned) | B48: avg best seed - 43 | C48: =Results!C72 - C3 -> 0.0013333333 | D48: =Results!D72 - D3 -> 0.0073333333 | E48: =Results!E72 - E3 -> -0.018666667 | F48: =Results!F72 - F3 -> -0.0026666667 | G48: =Results!G72 - G3 -> 0 | H48: =Results!H72 - H3 -> -0.0093333333 | I48: =Results!I72 - I3 -> 0.047666667 | J48: =Results!J72 - J3 -> -0.019 | ... N48: =Results!N72 - N3 -> 9 | P48: =Results!P72 - P3 -> -0.0046666667 | Q48: =Results!Q72 - Q3 -> 0.0013333333 | R48: =Results!R72 - R3 -> -0.011333333 | S48: =Results!S72 - S3 -> -0.0093333333 | T48: =Results!T72 - T3 -> 0.0053333333 | U48: =Results!U72 - U3 -> -0.005 | V48: =Results!V72 - V3 -> 0.021333333 | W48: =Results!W72 - W3 -> -0.0056666667 | ... AB48: =Results!AB72 - AB3 -> 0

Sheet Swin
A1: Multimodal Model | B1: Seed | C1: Tabular | D1: Image Subset | E1: cv | F1: Best Model | S1: Final Model
F2: ROC AUC | G2: Recall | H2: Balanced Accuracy | I2: F1-score | J2: PPV | K2: Matthews corrcoef | L2: Specificity | M2: NPV | N2: TP (CS) | O2: FN | P2: FP | Q2: TN (VD) | R2: Confusion Matrix | S2: ROC AUC | T2: Recall | U2: Balanced Accuracy | V2: F1-score | W2: PPV | X2: Matthews corrcoef | Y2: Specificity | Z2: NPV | AA2: TP (CS) | AB2: FN | AC2: FP | AD2: TN (VD)
C3: TEST RESULTS ON RETROSPECTIVE DATASET
A5: MM1 Bárbara (TabTransformer + Swin Transformer from AutoMM) | B5: 1 | C5: TRUE | D5: all (abdomen, femur, head) | E5: cv1 | F5: 0.77 | G5: 0.748 | H5: 0.685 | I5: 0.743 | J5: 0.741 | K5: 0.385 | L5: 0.846 | M5: 0.803 | N5: 43 | O5: 39 | P5: 29 | Q5: 159 | S5: 0.768 | T5: 0.752 | U5: 0.712 | V5: 0.753 | W5: 0.755 | X5: 0.419 | Y5: 0.814 | Z5: 0.827 | AA5: 50 | AB5: 32 | AC5: 35 | AD5: 153
C6: TRUE | D6: all (abdomen, femur, head) | E6: cv2 | F6: 0.751 | G6: 0.721 | H6: 0.586 | I6: 0.68 | J6: 0.695 | K6: 0.238 | L6: 0.926 | M6: 0.74 | N6: 20 | O6: 61 | P6: 14 | Q6: 174 | S6: 0.722 | T6: 0.729 | U6: 0.658 | V6: 0.723 | W6: 0.719 | X6: 0.331 | Y6: 0.835 | Z6: 0.789 | AA6: 39 | AB6: 42 | AC6: 31 | AD6: 157
C7: TRUE | D7: all (abdomen, femur, head) | E7: cv3 | F7: 0.793 | G7: 0.71 | H7: 0.586 | I7: 0.675 | J7: 0.681 | K7: 0.223 | L7: 0.904 | M7: 0.738 | N7: 22 | O7: 60 | P7: 18 | Q7: 169 | S7: 0.783 | T7: 0.721 | U7: 0.666 | V7: 0.72 | W7: 0.718 | X7: 0.335 | Y7: 0.807 | Z7: 0.795 | AA7: 43 | AB7: 39 | AC7: 36 | AD7: 151
B8: average | F8: =AVERAGE(F5:F7) -> 0.77133333 | G8: =AVERAGE(G5:G7) -> 0.72633333 | H8: =AVERAGE(H5:H7) -> 0.619 | I8: =AVERAGE(I5:I7) -> 0.69933333 | J8: =AVERAGE(J5:J7) -> 0.70566667 | K8: =AVERAGE(K5:K7) -> 0.282 | L8: =AVERAGE(L5:L7) -> 0.892 | M8: =AVERAGE(M5:M7) -> 0.76033333 | ... Q8: =AVERAGE(Q5:Q7) -> 167.33333 | S8: =AVERAGE(S5:S7) -> 0.75766667 | T8: =AVERAGE(T5:T7) -> 0.734 | U8: =AVERAGE(U5:U7) -> 0.67866667 | V8: =AVERAGE(V5:V7) -> 0.732 | W8: =AVERAGE(W5:W7) -> 0.73066667 | X8: =AVERAGE(X5:X7) -> 0.36166667 | Y8: =AVERAGE(Y5:Y7) -> 0.81866667 | Z8: =AVERAGE(Z5:Z7) -> 0.80366667 | ... AD8: =AVERAGE(AD5:AD7) -> 153.66667
B9: standard deviation | F9: =STDEV(F5:F7) -> 0.021031722 | G9: =STDEV(G5:G7) -> 0.019553346 | H9: =STDEV(H5:H7) -> 0.057157677 | I9: =STDEV(I5:I7) -> 0.037898989 | J9: =STDEV(J5:J7) -> 0.03139002 | K9: =STDEV(K5:K7) -> 0.089515362 | L9: =STDEV(L5:L7) -> 0.041327957 | M9: =STDEV(M5:M7) -> 0.036963946 | ... Q9: =STDEV(Q5:Q7) -> 7.6376262 | S9: =STDEV(S5:S7) -> 0.031785741 | T9: =STDEV(T5:T7) -> 0.016093477 | U9: =STDEV(U5:U7) -> 0.029143324 | V9: =STDEV(V5:V7) -> 0.018248288 | W9: =STDEV(W5:W7) -> 0.021079216 | X9: =STDEV(X5:X7) -> 0.049692387 | Y9: =STDEV(Y5:Y7) -> 0.014571662 | Z9: =STDEV(Z5:Z7) -> 0.020428738 | ... AD9: =STDEV(AD5:AD7) -> 3.0550505
A10: MM1 Bárbara (TabTransformer + Swin Transformer from AutoMM) | B10: 10 | C10: TRUE | D10: all (abdomen, femur, head) | E10: cv1 | F10: 0.766 | G10: 0.767 | H10: 0.698 | I10: 0.759 | J10: 0.757 | K10: 0.422 | L10: 0.872 | M10: 0.808 | N10: 43 | O10: 39 | P10: 24 | Q10: 164 | S10: 0.749 | T10: 0.737 | U10: 0.691 | V10: 0.737 | W10: 0.738 | X10: 0.38 | Y10: 0.809 | Z10: 0.813 | AA10: 47 | AB10: 35 | AC10: 37 | AD10: 152
C11: TRUE | D11: all (abdomen, femur, head) | E11: cv2 | F11: 0.751 | G11: 0.74 | H11: 0.677 | I11: 0.736 | J11: 0.733 | K11: 0.365 | L11: 0.835 | M11: 0.801 | N11: 42 | O11: 39 | P11: 31 | Q11: 157 | S11: 0.735 | T11: 0.699 | U11: 0.662 | V11: 0.704 | W11: 0.711 | X11: 0.313 | Y11: 0.755 | Z11: 0.802 | AA11: 46 | AB11: 35 | AC11: 46 | AD11: 142
C12: TRUE | D12: all (abdomen, femur, head) | E12: cv3 | F12: 0.673 | G12: 0.695 | H12: 0.5 | I12: 0.57 | J12: 0.788 | K12: 0 | L12: 1 | M12: 0.695 | N12: 0 | O12: 82 | P12: 0 | Q12: 187 | S12: 0.782 | T12: 0.721 | U12: 0.728 | V12: 0.731 | W12: 0.762 | X12: 0.424 | Y12: 0.711 | Z12: 0.864 | AA12: 61 | AB12: 21 | AC12: 54 | AD12: 133
B13: average | F13: =AVERAGE(F10:F12) -> 0.73 | G13: =AVERAGE(G10:G12) -> 0.734 | H13: =AVERAGE(H10:H12) -> 0.625 | I13: =AVERAGE(I10:I12) -> 0.68833333 | J13: =AVERAGE(J10:J12) -> 0.75933333 | K13: =AVERAGE(K10:K12) -> 0.26233333 | L13: =AVERAGE(L10:L12) -> 0.90233333 | M13: =AVERAGE(M10:M12) -> 0.768 | ... Q13: =AVERAGE(Q10:Q12) -> 169.33333 | S13: =AVERAGE(S10:S12) -> 0.75533333 | T13: =AVERAGE(T10:T12) -> 0.719 | U13: =AVERAGE(U10:U12) -> 0.69366667 | V13: =AVERAGE(V10:V12) -> 0.724 | W13: =AVERAGE(W10:W12) -> 0.737 | X13: =AVERAGE(X10:X12) -> 0.37233333 | Y13: =AVERAGE(Y10:Y12) -> 0.75833333 | Z13: =AVERAGE(Z10:Z12) -> 0.82633333 | ... AD13: =AVERAGE(AD10:AD12) -> 142.33333
B14: standard deviation | F14: =STDEV(F10:F12) -> 0.049929951 | G14: =STDEV(G10:G12) -> 0.036373067 | H14: =STDEV(H10:H12) -> 0.10876121 | I14: =STDEV(I10:I12) -> 0.1031229 | J14: =STDEV(J10:J12) -> 0.027574142 | K14: =STDEV(K10:K12) -> 0.22896797 | L14: =STDEV(L10:L12) -> 0.086581368 | M14: =STDEV(M10:M12) -> 0.063316664 | ... Q14: =STDEV(Q10:Q12) -> 15.69501 | S14: =STDEV(S10:S12) -> 0.024131584 | T14: =STDEV(T10:T12) -> 0.019078784 | U14: =STDEV(U10:U12) -> 0.033080709 | V14: =STDEV(V10:V12) -> 0.017578396 | W14: =STDEV(W10:W12) -> 0.025514702 | X14: =STDEV(X10:X12) -> 0.055895736 | Y14: =STDEV(Y10:Y12) -> 0.04908496 | Z14: =STDEV(Z10:Z12) -> 0.033080709 | ... AD14: =STDEV(AD10:AD12) -> 9.504385
A15: MM1 Bárbara (TabTransformer + Swin Transformer from AutoMM) | B15: 100 | C15: TRUE | D15: all (abdomen, femur, head) | E15: cv1 | F15: 0.753 | G15: 0.73 | H15: 0.661 | I15: 0.724 | J15: 0.72 | K15: 0.337 | L15: 0.835 | M15: 0.789 | N15: 40 | O15: 42 | P15: 31 | Q15: 157 | S15: 0.782 | T15: 0.715 | U15: 0.733 | V15: 0.726 | W15: 0.769 | X15: 0.431 | Y15: 0.686 | Z15: 0.878 | AA15: 64 | AB15: 18 | AC15: 59 | AD15: 129
C16: TRUE | D16: all (abdomen, femur, head) | E16: cv2 | F16: 0.761 | G16: 0.732 | H16: 0.679 | I16: 0.731 | J16: 0.73 | K16: 0.36 | L16: 0.814 | M16: 0.805 | N16: 44 | O16: 37 | P16: 35 | Q16: 153 | S16: 0.755 | T16: 0.74 | U16: 0.659 | V16: 0.729 | W16: 0.726 | X16: 0.345 | Y16: 0.862 | Z16: 0.786 | AA16: 37 | AB16: 44 | AC16: 26 | AD16: 162
C17: TRUE | D17: all (abdomen, femur, head) | E17: cv3 | F17: 0.759 | G17: 0.714 | H17: 0.578 | I17: 0.669 | J17: 0.685 | K17: 0.22 | L17: 0.925 | M17: 0.733 | N17: 19 | O17: 63 | P17: 14 | Q17: 173 | S17: 0.777 | T17: 0.717 | U17: 0.656 | V17: 0.714 | W17: 0.712 | X17: 0.32 | Y17: 0.813 | Z17: 0.788 | AA17: 41 | AB17: 41 | AC17: 35 | AD17: 152
B18: average | F18: =AVERAGE(F15:F17) -> 0.75766667 | G18: =AVERAGE(G15:G17) -> 0.72533333 | H18: =AVERAGE(H15:H17) -> 0.63933333 | I18: =AVERAGE(I15:I17) -> 0.708 | J18: =AVERAGE(J15:J17) -> 0.71166667 | K18: =AVERAGE(K15:K17) -> 0.30566667 | L18: =AVERAGE(L15:L17) -> 0.858 | M18: =AVERAGE(M15:M17) -> 0.77566667 | ... Q18: =AVERAGE(Q15:Q17) -> 161 | S18: =AVERAGE(S15:S17) -> 0.77133333 | T18: =AVERAGE(T15:T17) -> 0.724 | U18: =AVERAGE(U15:U17) -> 0.68266667 | V18: =AVERAGE(V15:V17) -> 0.723 | W18: =AVERAGE(W15:W17) -> 0.73566667 | X18: =AVERAGE(X15:X17) -> 0.36533333 | Y18: =AVERAGE(Y15:Y17) -> 0.787 | Z18: =AVERAGE(Z15:Z17) -> 0.81733333 | ... AD18: =AVERAGE(AD15:AD17) -> 147.66667
B19: standard deviation | F19: =STDEV(F15:F17) -> 0.004163332 | G19: =STDEV(G15:G17) -> 0.0098657657 | H19: =STDEV(H15:H17) -> 0.053873308 | I19: =STDEV(I15:I17) -> 0.033955854 | J19: =STDEV(J15:J17) -> 0.023629078 | K19: =STDEV(K15:K17) -> 0.075075518 | L19: =STDEV(L15:L17) -> 0.058966092 | M19: =STDEV(M15:M17) -> 0.037806525 | ... Q19: =STDEV(Q15:Q17) -> 10.583005 | S19: =STDEV(S15:S17) -> 0.014364308 | T19: =STDEV(T15:T17) -> 0.013892444 | U19: =STDEV(U15:U17) -> 0.043615746 | V19: =STDEV(V15:V17) -> 0.0079372539 | W19: =STDEV(W15:W17) -> 0.029704096 | X19: =STDEV(X15:X17) -> 0.058226569 | Y19: =STDEV(Y15:Y17) -> 0.090835015 | Z19: =STDEV(Z15:Z17) -> 0.05254839 | ... AD19: =STDEV(AD15:AD17) -> 16.921387
A20: MM1 Bárbara (TabTransformer + Swin Transformer from AutoMM) | B20: 2025 | C20: TRUE | D20: all (abdomen, femur, head) | E20: cv1 | F20: 0.751 | G20: 0.73 | H20: 0.696 | I20: 0.733 | J20: 0.739 | K20: 0.381 | L20: 0.782 | M20: 0.821 | N20: 50 | O20: 32 | P20: 41 | Q20: 147 | S20: 0.768 | T20: 0.744 | U20: 0.696 | V20: 0.744 | W20: 0.744 | X20: 0.394 | Y20: 0.819 | Z20: 0.815 | AA20: 47 | AB20: 35 | AC20: 34 | AD20: 154
C21: TRUE | D21: all (abdomen, femur, head) | E21: cv2 | F21: 0.744 | G21: 0.714 | H21: 0.672 | I21: 0.717 | J21: 0.721 | K21: 0.337 | L21: 0.777 | M21: 0.807 | N21: 46 | O21: 35 | P21: 42 | Q21: 146 | S21: 0.724 | T21: 0.703 | U21: 0.608 | V21: 0.687 | W21: 0.682 | X21: 0.24 | Y21: 0.846 | Z21: 0.757 | AA21: 30 | AB21: 51 | AC21: 29 | AD21: 159
C22: TRUE | D22: all (abdomen, femur, head) | E22: cv3 | F22: 0.797 | G22: 0.729 | H22: 0.569 | I22: 0.66 | J22: 0.738 | K22: 0.259 | L22: 0.979 | M22: 0.726 | N22: 13 | O22: 69 | P22: 4 | Q22: 183 | S22: 0.766 | T22: 0.721 | U22: 0.666 | V22: 0.72 | W22: 0.718 | X22: 0.335 | Y22: 0.807 | Z22: 0.795 | AA22: 43 | AB22: 39 | AC22: 36 | AD22: 151
B23: average | F23: =AVERAGE(F20:F22) -> 0.764 | G23: =AVERAGE(G20:G22) -> 0.72433333 | H23: =AVERAGE(H20:H22) -> 0.64566667 | I23: =AVERAGE(I20:I22) -> 0.70333333 | J23: =AVERAGE(J20:J22) -> 0.73266667 | K23: =AVERAGE(K20:K22) -> 0.32566667 | L23: =AVERAGE(L20:L22) -> 0.846 | M23: =AVERAGE(M20:M22) -> 0.78466667 | ... Q23: =AVERAGE(Q20:Q22) -> 158.66667 | S23: =AVERAGE(S20:S22) -> 0.75266667 | T23: =AVERAGE(T20:T22) -> 0.72266667 | U23: =AVERAGE(U20:U22) -> 0.65666667 | V23: =AVERAGE(V20:V22) -> 0.717 | W23: =AVERAGE(W20:W22) -> 0.71466667 | X23: =AVERAGE(X20:X22) -> 0.323 | Y23: =AVERAGE(Y20:Y22) -> 0.824 | Z23: =AVERAGE(Z20:Z22) -> 0.789 | ... AD23: =AVERAGE(AD20:AD22) -> 154.66667
B24: standard deviation | F24: =STDEV(F20:F22) -> 0.02879236 | G24: =STDEV(G20:G23) -> 0.0073181661 | H24: =STDEV(H20:H23) -> 0.055089826 | I24: =STDEV(I20:I23) -> 0.031329787 | J24: =STDEV(J20:J23) -> 0.0082596745 | K24: =STDEV(K20:K23) -> 0.050446892 | L24: =STDEV(L20:L23) -> 0.094067352 | M24: =STDEV(M20:M23) -> 0.041875477 | N24: =STDEV(N20:N23) -> 16.579773 | ... Q24: =STDEV(Q20:Q23) -> 17.211108 | S24: =STDEV(S20:S23) -> 0.020286832 | T24: =STDEV(T20:T23) -> 0.016779617 | U24: =STDEV(U20:U23) -> 0.036527007 | V24: =STDEV(V20:V23) -> 0.023366643 | W24: =STDEV(W20:W23) -> 0.025420901 | X24: =STDEV(X20:X23) -> 0.063440261 | Y24: =STDEV(Y20:Y23) -> 0.016309506 | Z24: =STDEV(Z20:Z23) -> 0.024055491 | ... AD24: =STDEV(AD20:AD23) -> 3.2998316
A25: MM1 Bárbara (TabTransformer + Swin Transformer from AutoMM) | B25: 21 | C25: TRUE | D25: all (abdomen, femur, head) | E25: cv1 | F25: 0.791 | G25: 0.752 | H25: 0.708 | I25: 0.752 | J25: 0.753 | K25: 0.415 | L25: 0.819 | M25: 0.824 | N25: 49 | O25: 33 | P25: 34 | Q25: 154 | S25: 0.78 | T25: 0.73 | U25: 0.713 | V25: 0.736 | W25: 0.75 | X25: 0.405 | Y25: 0.755 | Z25: 0.84 | AA25: 55 | AB25: 27 | AC25: 46 | AD25: 142
C26: TRUE | D26: all (abdomen, femur, head) | E26: cv2 | F26: 0.762 | G26: 0.747 | H26: 0.682 | I26: 0.742 | J26: 0.739 | K26: 0.379 | L26: 0.846 | M26: 0.803 | N26: 42 | O26: 39 | P26: 29 | Q26: 159 | S26: 0.75 | T26: 0.732 | U26: 0.689 | V26: 0.734 | W26: 0.736 | X26: 0.373 | Y26: 0.798 | Z26: 0.815 | AA26: 47 | AB26: 34 | AC26: 38 | AD26: 150
C27: TRUE | D27: all (abdomen, femur, head) | E27: cv3 | F27: 0.797 | G27: 0.729 | H27: 0.661 | I27: 0.723 | J27: 0.719 | K27: 0.336 | L27: 0.834 | M27: 0.788 | N27: 40 | O27: 42 | P27: 31 | Q27: 156 | S27: 0.782 | T27: 0.725 | U27: 0.641 | V27: 0.713 | W27: 0.709 | X27: 0.309 | Y27: 0.856 | Z27: 0.773 | AA27: 35 | AB27: 47 | AC27: 27 | AD27: 160
B28: average | F28: =AVERAGE(F25:F27) -> 0.78333333 | G28: =AVERAGE(G25:G27) -> 0.74266667 | H28: =AVERAGE(H25:H27) -> 0.68366667 | I28: =AVERAGE(I25:I27) -> 0.739 | J28: =AVERAGE(J25:J27) -> 0.737 | K28: =AVERAGE(K25:K27) -> 0.37666667 | L28: =AVERAGE(L25:L27) -> 0.833 | M28: =AVERAGE(M25:M27) -> 0.805 | ... Q28: =AVERAGE(Q25:Q27) -> 156.33333 | S28: =AVERAGE(S25:S27) -> 0.77066667 | T28: =AVERAGE(T25:T27) -> 0.729 | U28: =AVERAGE(U25:U27) -> 0.681 | V28: =AVERAGE(V25:V27) -> 0.72766667 | W28: =AVERAGE(W25:W27) -> 0.73166667 | X28: =AVERAGE(X25:X27) -> 0.36233333 | Y28: =AVERAGE(Y25:Y27) -> 0.803 | Z28: =AVERAGE(Z25:Z27) -> 0.80933333 | ... AD28: =AVERAGE(AD25:AD27) -> 150.66667
B29: standard deviation | F29: =STDEV(F25:F27) -> 0.018717194 | G29: =STDEV(G25:G27) -> 0.012096832 | H29: =STDEV(H25:H27) -> 0.023544285 | I29: =STDEV(I25:I27) -> 0.01473092 | J29: =STDEV(J25:J27) -> 0.017088007 | K29: =STDEV(K25:K27) -> 0.039551654 | L29: =STDEV(L25:L27) -> 0.013527749 | M29: =STDEV(M25:M27) -> 0.018083141 | ... Q29: =STDEV(Q25:Q27) -> 2.5166115 | S29: =STDEV(S25:S27) -> 0.017925773 | T29: =STDEV(T25:T27) -> 0.0036055513 | U29: =STDEV(U25:U27) -> 0.036660606 | V29: =STDEV(V25:V27) -> 0.01274101 | W29: =STDEV(W25:W27) -> 0.020840665 | X29: =STDEV(X25:X27) -> 0.048880807 | Y29: =STDEV(Y25:Y27) -> 0.050685304 | Z29: =STDEV(Z25:Z27) -> 0.033857545 | ... AD29: =STDEV(AD25:AD27) -> 9.0184995
A30: MM1 Bárbara (TabTransformer + Swin Transformer from AutoMM) | B30: 336 | C30: TRUE | D30: all (abdomen, femur, head) | E30: cv1 | F30: 0.777 | G30: 0.748 | H30: 0.695 | I30: 0.746 | J30: 0.745 | K30: 0.396 | L30: 0.83 | M30: 0.812 | N30: 46 | O30: 36 | P30: 32 | Q30: 156 | S30: 0.777 | T30: 0.726 | U30: 0.731 | V30: 0.736 | W30: 0.765 | X30: 0.43 | Y30: 0.718 | Z30: 0.865 | AA30: 61 | AB30: 21 | AC30: 53 | AD30: 135
C31: TRUE | D31: all (abdomen, femur, head) | E31: cv2 | F31: 0.744 | G31: 0.758 | H31: 0.68 | I31: 0.748 | J31: 0.746 | K31: 0.391 | L31: 0.878 | M31: 0.797 | N31: 39 | O31: 42 | P31: 23 | Q31: 165 | S31: 0.754 | T31: 0.766 | U31: 0.692 | V31: 0.757 | W31: 0.755 | X31: 0.414 | Y31: 0.878 | Z31: 0.805 | AA31: 41 | AB31: 40 | AC31: 23 | AD31: 165
C32: TRUE | D32: all (abdomen, femur, head) | E32: cv3 | F32: 0.779 | G32: 0.706 | H32: 0.518 | I32: 0.595 | J32: 0.794 | K32: 0.16 | L32: 1 | M32: 0.703 | N32: 3 | O32: 79 | P32: 0 | Q32: 187 | S32: 0.792 | T32: 0.729 | U32: 0.668 | V32: 0.725 | W32: 0.723 | X32: 0.345 | Y32: 0.824 | Z32: 0.794 | AA32: 42 | AB32: 40 | AC32: 33 | AD32: 154
B33: average | F33: =AVERAGE(F30:F32) -> 0.76666667 | G33: =AVERAGE(G30:G32) -> 0.73733333 | H33: =AVERAGE(H30:H32) -> 0.631 | I33: =AVERAGE(I30:I32) -> 0.69633333 | J33: =AVERAGE(J30:J32) -> 0.76166667 | K33: =AVERAGE(K30:K32) -> 0.31566667 | L33: =AVERAGE(L30:L32) -> 0.90266667 | M33: =AVERAGE(M30:M32) -> 0.77066667 | ... Q33: =AVERAGE(Q30:Q32) -> 169.33333 | S33: =AVERAGE(S30:S32) -> 0.77433333 | T33: =AVERAGE(T30:T32) -> 0.74033333 | U33: =AVERAGE(U30:U32) -> 0.697 | V33: =AVERAGE(V30:V32) -> 0.73933333 | W33: =AVERAGE(W30:W32) -> 0.74766667 | X33: =AVERAGE(X30:X32) -> 0.39633333 | Y33: =AVERAGE(Y30:Y32) -> 0.80666667 | Z33: =AVERAGE(Z30:Z32) -> 0.82133333 | ... AD33: =AVERAGE(AD30:AD32) -> 151.33333
B34: standard deviation | F34: =STDEV(F30:F32) -> 0.019655364 | G34: =STDEV(G30:G32) -> 0.027592269 | H34: =STDEV(H30:H32) -> 0.098147848 | I34: =STDEV(I30:I32) -> 0.087762938 | J34: =STDEV(J30:J32) -> 0.028005952 | K34: =STDEV(K30:K32) -> 0.13483447 | L34: =STDEV(L30:L32) -> 0.087643216 | M34: =STDEV(M30:M32) -> 0.059079043 | ... Q34: =STDEV(Q30:Q32) -> 15.947832 | S34: =STDEV(S30:S32) -> 0.019139836 | T34: =STDEV(T30:T32) -> 0.02227854 | U34: =STDEV(U30:U32) -> 0.031796226 | V34: =STDEV(V30:V32) -> 0.016258331 | W34: =STDEV(W30:W32) -> 0.02193931 | X34: =STDEV(X30:X32) -> 0.045170049 | Y34: =STDEV(Y30:Y32) -> 0.081396151 | Z34: =STDEV(Z30:Z32) -> 0.038214308 | ... AD34: =STDEV(AD30:AD32) -> 15.176737
A35: MM1 Bárbara (TabTransformer + Swin Transformer from AutoMM) | B35: 43 | C35: TRUE | D35: all (abdomen, femur, head) | E35: cv1 | F35: 0.772 | G35: 0.744 | H35: 0.693 | I35: 0.743 | J35: 0.742 | K35: 0.39 | L35: 0.824 | M35: 0.812 | N35: 46 | O35: 36 | P35: 33 | Q35: 155 | S35: 0.761 | T35: 0.756 | U35: 0.714 | V35: 0.756 | W35: 0.757 | X35: 0.426 | Y35: 0.819 | Z35: 0.828 | AA35: 50 | AB35: 32 | AC35: 34 | AD35: 154
C36: TRUE | D36: all (abdomen, femur, head) | E36: cv2 | F36: 0.754 | G36: 0.743 | H36: 0.655 | I36: 0.73 | J36: 0.728 | K36: 0.346 | L36: 0.878 | M36: 0.782 | N36: 35 | O36: 46 | P36: 23 | Q36: 165 | S36: 0.721 | T36: 0.71 | U36: 0.624 | V36: 0.699 | W36: 0.694 | X36: 0.268 | Y36: 0.84 | Z36: 0.767 | AA36: 33 | AB36: 48 | AC36: 30 | AD36: 158
C37: TRUE | D37: all (abdomen, femur, head) | E37: cv3 | F37: 0.79 | G37: 0.695 | H37: 0.5 | I37: 0.57 | J37: 0.788 | K37: 0 | L37: 1 | M37: 0.695 | N37: 0 | O37: 82 | P37: 0 | Q37: 187 | S37: 0.784 | T37: 0.717 | U37: 0.612 | V37: 0.694 | W37: 0.694 | X37: 0.265 | Y37: 0.882 | Z37: 0.753 | AA37: 28 | AB37: 54 | AC37: 22 | AD37: 165
B38: average | F38: =AVERAGE(F35:F37) -> 0.772 | G38: =AVERAGE(G35:G37) -> 0.72733333 | H38: =AVERAGE(H35:H37) -> 0.616 | I38: =AVERAGE(I35:I37) -> 0.681 | J38: =AVERAGE(J35:J37) -> 0.75266667 | K38: =AVERAGE(K35:K37) -> 0.24533333 | L38: =AVERAGE(L35:L37) -> 0.90066667 | M38: =AVERAGE(M35:M37) -> 0.763 | ... Q38: =AVERAGE(Q35:Q37) -> 169 | S38: =AVERAGE(S35:S37) -> 0.75533333 | T38: =AVERAGE(T35:T37) -> 0.72766667 | U38: =AVERAGE(U35:U37) -> 0.65 | V38: =AVERAGE(V35:V37) -> 0.71633333 | W38: =AVERAGE(W35:W37) -> 0.715 | X38: =AVERAGE(X35:X37) -> 0.31966667 | Y38: =AVERAGE(Y35:Y37) -> 0.847 | Z38: =AVERAGE(Z35:Z37) -> 0.78266667 | ... AD38: =AVERAGE(AD35:AD37) -> 159
B39: standard deviation | F39: =STDEV(F35:F37) -> 0.018 | G39: =STDEV(G35:G37) -> 0.028005952 | H39: =STDEV(H35:H37) -> 0.10223991 | I39: =STDEV(I35:I37) -> 0.096348326 | J39: =STDEV(J35:J37) -> 0.03139002 | K39: =STDEV(K35:K37) -> 0.21360087 | L39: =STDEV(L35:L37) -> 0.090162816 | M39: =STDEV(M35:M37) -> 0.060770058 | ... Q39: =STDEV(Q35:Q37) -> 16.370706 | S39: =STDEV(S35:S37) -> 0.031879983 | T39: =STDEV(T35:T37) -> 0.024785749 | U39: =STDEV(U35:U37) -> 0.055749439 | V39: =STDEV(V35:V37) -> 0.03444319 | W39: =STDEV(W35:W37) -> 0.036373067 | X39: =STDEV(X35:X37) -> 0.092099584 | Y39: =STDEV(Y35:Y37) -> 0.03207803 | Z39: =STDEV(Z35:Z37) -> 0.039878984 | ... AD39: =STDEV(AD35:AD37) -> 5.5677644
A40: MM1 Bárbara (TabTransformer + Swin Transformer from AutoMM) | B40: 50 | C40: TRUE | D40: all (abdomen, femur, head) | E40: cv1 | F40: 0.77 | G40: 0.756 | H40: 0.663 | I40: 0.739 | J40: 0.742 | K40: 0.375 | L40: 0.899 | M40: 0.782 | N40: 35 | O40: 47 | P40: 19 | Q40: 169 | S40: 0.775 | T40: 0.744 | U40: 0.713 | V40: 0.748 | W40: 0.753 | X40: 0.415 | Y40: 0.793 | Z40: 0.832 | AA40: 52 | AB40: 30 | AC40: 39 | AD40: 149
C41: TRUE | D41: all (abdomen, femur, head) | E41: cv2 | F41: 0.753 | G41: 0.743 | H41: 0.651 | I41: 0.728 | J41: 0.727 | K41: 0.342 | L41: 0.883 | M41: 0.779 | N41: 34 | O41: 47 | P41: 22 | Q41: 166 | S41: 0.761 | T41: 0.725 | U41: 0.652 | V41: 0.718 | W41: 0.714 | X41: 0.32 | Y41: 0.835 | Z41: 0.785 | AA41: 38 | AB41: 43 | AC41: 31 | AD41: 157
...

Sheet FetalCLIP
A1: Multimodal Model | B1: Seed | C1: Tabular | D1: Image Subset | E1: cv | F1: Best Model | S1: Final Model
F2: ROC AUC | G2: Recall | H2: Balanced Accuracy | I2: F1-score | J2: PPV | K2: Matthews corrcoef | L2: Specificity | M2: NPV | N2: TP (CS) | O2: FN | P2: FP | Q2: TN (VD) | R2: Confusion Matrix | S2: ROC AUC | T2: Recall | U2: Balanced Accuracy | V2: F1-score | W2: PPV | X2: Matthews corrcoef | Y2: Specificity | Z2: NPV | AA2: TP (CS) | AB2: FN | AC2: FP | AD2: TN (VD)
C3: TEST RESULTS ON RETROSPECTIVE DATASET
A5: TabTransformer + FetalCLIP | B5: 1 | C5: TRUE | D5: all (abdomen, femur, head) | E5: cv1 | F5: 0.798 | G5: 0.737 | H5: 0.698 | I5: 0.739 | J5: 0.742 | K5: 0.389 | L5: 0.798 | M5: 0.82 | N5: 49 | O5: 33 | P5: 38 | Q5: 150 | S5: 0.807 | T5: 0.774 | U5: 0.707 | V5: 0.767 | W5: 0.765 | X5: 0.441 | Y5: 0.878 | Z5: 0.813 | AA5: 44 | AB5: 38 | AC5: 23 | AD5: 165
C6: TRUE | D6: all (abdomen, femur, head) | E6: cv2 | F6: 0.741 | G6: 0.755 | H6: 0.712 | I6: 0.755 | J6: 0.756 | K6: 0.421 | L6: 0.819 | M6: 0.828 | N6: 49 | O6: 32 | P6: 34 | Q6: 154 | S6: 0.725 | T6: 0.695 | U6: 0.634 | V6: 0.694 | W6: 0.693 | X6: 0.271 | Y6: 0.787 | Z6: 0.779 | AA6: 39 | AB6: 42 | AC6: 40 | AD6: 148
C7: TRUE | D7: all (abdomen, femur, head) | E7: cv3 | F7: 0.786 | G7: 0.721 | H7: 0.642 | I7: 0.711 | J7: 0.707 | K7: 0.305 | L7: 0.845 | M7: 0.775 | N7: 36 | O7: 46 | P7: 29 | Q7: 158 | S7: 0.765 | T7: 0.71 | U7: 0.658 | V7: 0.71 | W7: 0.71 | X7: 0.316 | Y7: 0.791 | Z7: 0.791 | AA7: 43 | AB7: 39 | AC7: 39 | AD7: 148
B8: average | F8: =AVERAGE(F5:F7) -> 0.775 | G8: =AVERAGE(G5:G7) -> 0.73766667 | H8: =AVERAGE(H5:H7) -> 0.684 | I8: =AVERAGE(I5:I7) -> 0.735 | J8: =AVERAGE(J5:J7) -> 0.735 | K8: =AVERAGE(K5:K7) -> 0.37166667 | L8: =AVERAGE(L5:L7) -> 0.82066667 | M8: =AVERAGE(M5:M7) -> 0.80766667 | ... Q8: =AVERAGE(Q5:Q7) -> 154 | S8: =AVERAGE(S5:S7) -> 0.76566667 | T8: =AVERAGE(T5:T7) -> 0.72633333 | U8: =AVERAGE(U5:U7) -> 0.66633333 | V8: =AVERAGE(V5:V7) -> 0.72366667 | W8: =AVERAGE(W5:W7) -> 0.72266667 | X8: =AVERAGE(X5:X7) -> 0.34266667 | Y8: =AVERAGE(Y5:Y7) -> 0.81866667 | Z8: =AVERAGE(Z5:Z7) -> 0.79433333 | ... AD8: =AVERAGE(AD5:AD7) -> 153.66667
B9: standard deviation | F9: =STDEV(F5:F7) -> 0.030049958 | G9: =STDEV(G5:G7) -> 0.017009801 | H9: =STDEV(H5:H7) -> 0.037040518 | I9: =STDEV(I5:I7) -> 0.022271057 | J9: =STDEV(J5:J7) -> 0.025238859 | K9: =STDEV(K5:K7) -> 0.059911045 | L9: =STDEV(L5:L7) -> 0.023544285 | M9: =STDEV(M5:M7) -> 0.028571548 | ... Q9: =STDEV(Q5:Q7) -> 4 | S9: =STDEV(S5:S7) -> 0.041004065 | T9: =STDEV(T5:T7) -> 0.041956327 | U9: =STDEV(U5:U7) -> 0.03720663 | V9: =STDEV(V5:V7) -> 0.038370996 | W9: =STDEV(W5:W7) -> 0.037634204 | X9: =STDEV(X5:X7) -> 0.088081402 | Y9: =STDEV(Y5:Y7) -> 0.051423082 | Z9: =STDEV(Z5:Z7) -> 0.017243356 | ... AD9: =STDEV(AD5:AD7) -> 9.8149546
A10: TabTransformer + FetalCLIP | B10: 10 | C10: TRUE | D10: all (abdomen, femur, head) | E10: cv1 | F10: 0.765 | G10: 0.756 | H10: 0.687 | I10: 0.749 | J10: 0.746 | K10: 0.396 | L10: 0.862 | M10: 0.802 | N10: 42 | O10: 40 | P10: 26 | Q10: 162 | S10: 0.796 | T10: 0.774 | U10: 0.68 | V10: 0.756 | W10: 0.764 | X10: 0.422 | Y10: 0.92 | Z10: 0.79 | AA10: 36 | AB10: 46 | AC10: 15 | AD10: 173
C11: TRUE | D11: all (abdomen, femur, head) | E11: cv2 | F11: 0.712 | G11: 0.732 | H11: 0.619 | I11: 0.706 | J11: 0.711 | K11: 0.292 | L11: 0.904 | M11: 0.759 | N11: 27 | O11: 54 | P11: 18 | Q11: 170 | S11: 0.701 | T11: 0.721 | U11: 0.66 | V11: 0.719 | W11: 0.716 | X11: 0.326 | Y11: 0.814 | Z11: 0.793 | AA11: 41 | AB11: 40 | AC11: 35 | AD11: 153
C12: TRUE | D12: all (abdomen, femur, head) | E12: cv3 | F12: 0.759 | G12: 0.721 | H12: 0.628 | I12: 0.705 | J12: 0.702 | K12: 0.289 | L12: 0.866 | M12: 0.764 | N12: 32 | O12: 50 | P12: 25 | Q12: 162 | S12: 0.777 | T12: 0.699 | U12: 0.674 | V12: 0.706 | W12: 0.718 | X12: 0.332 | Y12: 0.738 | Z12: 0.812 | AA12: 50 | AB12: 32 | AC12: 49 | AD12: 138
B13: average | F13: =AVERAGE(F10:F12) -> 0.74533333 | G13: =AVERAGE(G10:G12) -> 0.73633333 | H13: =AVERAGE(H10:H12) -> 0.64466667 | I13: =AVERAGE(I10:I12) -> 0.72 | J13: =AVERAGE(J10:J12) -> 0.71966667 | K13: =AVERAGE(K10:K12) -> 0.32566667 | L13: =AVERAGE(L10:L12) -> 0.87733333 | M13: =AVERAGE(M10:M12) -> 0.775 | ... Q13: =AVERAGE(Q10:Q12) -> 164.66667 | S13: =AVERAGE(S10:S12) -> 0.758 | T13: =AVERAGE(T10:T12) -> 0.73133333 | U13: =AVERAGE(U10:U12) -> 0.67133333 | V13: =AVERAGE(V10:V12) -> 0.727 | W13: =AVERAGE(W10:W12) -> 0.73266667 | X13: =AVERAGE(X10:X12) -> 0.36 | Y13: =AVERAGE(Y10:Y12) -> 0.824 | Z13: =AVERAGE(Z10:Z12) -> 0.79833333 | ... AD13: =AVERAGE(AD10:AD12) -> 154.66667
B14: standard deviation | F14: =STDEV(F10:F12) -> 0.029022979 | G14: =STDEV(G10:G12) -> 0.017897858 | H14: =STDEV(H10:H12) -> 0.036936883 | I14: =STDEV(I10:I12) -> 0.025119713 | J14: =STDEV(J10:J12) -> 0.023245071 | K14: =STDEV(K10:K12) -> 0.06092892 | L14: =STDEV(L10:L12) -> 0.023180452 | M14: =STDEV(M10:M12) -> 0.023515952 | ... Q14: =STDEV(Q10:Q12) -> 4.6188022 | S14: =STDEV(S10:S12) -> 0.050269275 | T14: =STDEV(T10:T12) -> 0.038552994 | U14: =STDEV(U10:U12) -> 0.010263203 | V14: =STDEV(V10:V12) -> 0.025942244 | W14: =STDEV(W10:W12) -> 0.027153882 | X14: =STDEV(X10:X12) -> 0.053777319 | Y14: =STDEV(Y10:Y12) -> 0.091411159 | Z14: =STDEV(Z10:Z12) -> 0.011930353 | ... AD14: =STDEV(AD10:AD12) -> 17.559423
A15: TabTransformer + FetalCLIP | B15: 100 | C15: TRUE | D15: all (abdomen, femur, head) | E15: cv1 | F15: 0.736 | G15: 0.733 | H15: 0.692 | I15: 0.735 | J15: 0.737 | K15: 0.378 | L15: 0.798 | M15: 0.815 | N15: 48 | O15: 34 | P15: 38 | Q15: 150 | S15: 0.764 | T15: 0.756 | U15: 0.673 | V15: 0.743 | W15: 0.743 | X15: 0.383 | Y15: 0.883 | Z15: 0.79 | AA15: 38 | AB15: 44 | AC15: 22 | AD15: 166
C16: TRUE | D16: all (abdomen, femur, head) | E16: cv2 | F16: 0.743 | G16: 0.743 | H16: 0.669 | I16: 0.735 | J16: 0.732 | K16: 0.36 | L16: 0.856 | M16: 0.793 | N16: 39 | O16: 42 | P16: 27 | Q16: 161 | S16: 0.698 | T16: 0.721 | U16: 0.625 | V16: 0.704 | W16: 0.702 | X16: 0.282 | Y16: 0.867 | Z16: 0.765 | AA16: 31 | AB16: 50 | AC16: 25 | AD16: 163
C17: TRUE | D17: all (abdomen, femur, head) | E17: cv3 | F17: 0.802 | G17: 0.714 | H17: 0.589 | I17: 0.678 | J17: 0.686 | K17: 0.232 | L17: 0.909 | M17: 0.739 | N17: 22 | O17: 60 | P17: 17 | Q17: 170 | S17: 0.786 | T17: 0.725 | U17: 0.624 | V17: 0.704 | W17: 0.704 | X17: 0.289 | Y17: 0.882 | Z17: 0.76 | AA17: 30 | AB17: 52 | AC17: 22 | AD17: 165
B18: average | F18: =AVERAGE(F15:F17) -> 0.76033333 | G18: =AVERAGE(G15:G17) -> 0.73 | H18: =AVERAGE(H15:H17) -> 0.65 | I18: =AVERAGE(I15:I17) -> 0.716 | J18: =AVERAGE(J15:J17) -> 0.71833333 | K18: =AVERAGE(K15:K17) -> 0.32333333 | L18: =AVERAGE(L15:L17) -> 0.85433333 | M18: =AVERAGE(M15:M17) -> 0.78233333 | ... Q18: =AVERAGE(Q15:Q17) -> 160.33333 | S18: =AVERAGE(S15:S17) -> 0.74933333 | T18: =AVERAGE(T15:T17) -> 0.734 | U18: =AVERAGE(U15:U17) -> 0.64066667 | V18: =AVERAGE(V15:V17) -> 0.717 | W18: =AVERAGE(W15:W17) -> 0.71633333 | X18: =AVERAGE(X15:X17) -> 0.318 | Y18: =AVERAGE(Y15:Y17) -> 0.87733333 | Z18: =AVERAGE(Z15:Z17) -> 0.77166667 | ... AD18: =AVERAGE(AD15:AD17) -> 164.66667
B19: standard deviation | F19: =STDEV(F15:F17) -> 0.036253735 | G19: =STDEV(G15:G17) -> 0.01473092 | H19: =STDEV(H15:H17) -> 0.054064776 | I19: =STDEV(I15:I17) -> 0.032908965 | J19: =STDEV(J15:J17) -> 0.028112868 | K19: =STDEV(K15:K17) -> 0.07960737 | L19: =STDEV(L15:L17) -> 0.055518766 | M19: =STDEV(M15:M17) -> 0.039106692 | ... Q19: =STDEV(Q15:Q17) -> 10.016653 | S19: =STDEV(S15:S17) -> 0.045796652 | T19: =STDEV(T15:T17) -> 0.019157244 | U19: =STDEV(U15:U17) -> 0.028005952 | V19: =STDEV(V15:V17) -> 0.022516661 | W19: =STDEV(W15:W17) -> 0.023115651 | X19: =STDEV(X15:X17) -> 0.056400355 | Y19: =STDEV(Y15:Y17) -> 0.0089628864 | Z19: =STDEV(Z15:Z17) -> 0.016072751 | ... AD19: =STDEV(AD15:AD17) -> 1.5275252
A20: TabTransformer + FetalCLIP | B20: 2025 | C20: TRUE | D20: all (abdomen, femur, head) | E20: cv1 | F20: 0.751 | G20: 0.707 | H20: 0.663 | I20: 0.71 | J20: 0.713 | K20: 0.32 | L20: 0.777 | M20: 0.798 | N20: 45 | O20: 37 | P20: 42 | Q20: 146 | S20: 0.775 | T20: 0.737 | U20: 0.715 | V20: 0.743 | W20: 0.753 | X20: 0.412 | Y20: 0.771 | Z20: 0.838 | AA20: 54 | AB20: 28 | AC20: 43 | AD20: 145
C21: TRUE | D21: all (abdomen, femur, head) | E21: cv2 | F21: 0.726 | G21: 0.743 | H21: 0.62 | I21: 0.71 | J21: 0.728 | K21: 0.315 | L21: 0.931 | M21: 0.758 | N21: 25 | O21: 56 | P21: 13 | Q21: 175 | S21: 0.722 | T21: 0.71 | U21: 0.634 | V21: 0.703 | W21: 0.699 | X21: 0.282 | Y21: 0.824 | Z21: 0.775 | AA21: 36 | AB21: 45 | AC21: 33 | AD21: 155
C22: TRUE | D22: all (abdomen, femur, head) | E22: cv3 | F22: 0.799 | G22: 0.74 | H22: 0.662 | I22: 0.73 | J22: 0.727 | K22: 0.351 | L22: 0.861 | M22: 0.785 | N22: 38 | O22: 44 | P22: 26 | Q22: 161 | S22: 0.801 | T22: 0.751 | U22: 0.674 | V22: 0.741 | W22: 0.739 | X22: 0.377 | Y22: 0.872 | Z22: 0.791 | AA22: 39 | AB22: 43 | AC22: 24 | AD22: 163
B23: average | F23: =AVERAGE(F20:F22) -> 0.75866667 | G23: =AVERAGE(G20:G22) -> 0.73 | H23: =AVERAGE(H20:H22) -> 0.64833333 | I23: =AVERAGE(I20:I22) -> 0.71666667 | J23: =AVERAGE(J20:J22) -> 0.72266667 | K23: =AVERAGE(K20:K22) -> 0.32866667 | L23: =AVERAGE(L20:L22) -> 0.85633333 | M23: =AVERAGE(M20:M22) -> 0.78033333 | ... Q23: =AVERAGE(Q20:Q22) -> 160.66667 | S23: =AVERAGE(S20:S22) -> 0.766 | T23: =AVERAGE(T20:T22) -> 0.73266667 | U23: =AVERAGE(U20:U22) -> 0.67433333 | V23: =AVERAGE(V20:V22) -> 0.729 | W23: =AVERAGE(W20:W22) -> 0.73033333 | X23: =AVERAGE(X20:X22) -> 0.357 | Y23: =AVERAGE(Y20:Y22) -> 0.82233333 | Z23: =AVERAGE(Z20:Z22) -> 0.80133333 | ... AD23: =AVERAGE(AD20:AD22) -> 154.33333
B24: standard deviation | F24: =STDEV(F20:F22) -> 0.037098967 | G24: =STDEV(G20:G22) -> 0.019974984 | H24: =STDEV(H20:H22) -> 0.02454248 | I24: =STDEV(I20:I22) -> 0.011547005 | J24: =STDEV(J20:J22) -> 0.0083864971 | K24: =STDEV(K20:K22) -> 0.019502137 | L24: =STDEV(L20:L22) -> 0.077105988 | M24: =STDEV(M20:M22) -> 0.020404248 | ... Q24: =STDEV(Q20:Q22) -> 14.502873 | S24: =STDEV(S20:S22) -> 0.040261644 | T24: =STDEV(T20:T22) -> 0.020840665 | U24: =STDEV(U20:U22) -> 0.040501029 | V24: =STDEV(V20:V22) -> 0.022538855 | W24: =STDEV(W20:W22) -> 0.028023799 | X24: =STDEV(X20:X22) -> 0.06726812 | Y24: =STDEV(Y20:Y22) -> 0.050520623 | Z24: =STDEV(Z20:Z22) -> 0.032746501 | ... AD24: =STDEV(AD20:AD22) -> 9.0184995
A25: TabTransformer + FetalCLIP | B25: 21 | C25: TRUE | D25: all (abdomen, femur, head) | E25: cv1 | F25: 0.778 | G25: 0.741 | H25: 0.728 | I25: 0.748 | J25: 0.762 | K25: 0.432 | L25: 0.761 | M25: 0.851 | N25: 57 | O25: 25 | P25: 45 | Q25: 143 | S25: 0.752 | T25: 0.73 | U25: 0.665 | V25: 0.725 | W25: 0.722 | X25: 0.341 | Y25: 0.83 | Z25: 0.792 | AA25: 41 | AB25: 41 | AC25: 32 | AD25: 156
C26: TRUE | D26: all (abdomen, femur, head) | E26: cv2 | F26: 0.725 | G26: 0.74 | H26: 0.649 | I26: 0.725 | J26: 0.724 | K26: 0.334 | L26: 0.878 | M26: 0.778 | N26: 34 | O26: 47 | P26: 23 | Q26: 165 | S26: 0.708 | T26: 0.684 | U26: 0.605 | V26: 0.677 | W26: 0.672 | X26: 0.22 | Y26: 0.803 | Z26: 0.759 | AA26: 33 | AB26: 48 | AC26: 37 | AD26: 151
C27: TRUE | D27: all (abdomen, femur, head) | E27: cv3 | F27: 0.787 | G27: 0.732 | H27: 0.674 | I27: 0.729 | J27: 0.727 | K27: 0.356 | L27: 0.824 | M27: 0.798 | N27: 43 | O27: 39 | P27: 33 | Q27: 154 | S27: 0.766 | T27: 0.717 | U27: 0.653 | V27: 0.713 | W27: 0.71 | X27: 0.315 | Y27: 0.818 | Z27: 0.785 | AA27: 40 | AB27: 42 | AC27: 34 | AD27: 153
B28: average | F28: =AVERAGE(F25:F27) -> 0.76333333 | G28: =AVERAGE(G25:G27) -> 0.73766667 | H28: =AVERAGE(H25:H27) -> 0.68366667 | I28: =AVERAGE(I25:I27) -> 0.734 | J28: =AVERAGE(J25:J27) -> 0.73766667 | K28: =AVERAGE(K25:K27) -> 0.374 | L28: =AVERAGE(L25:L27) -> 0.821 | M28: =AVERAGE(M25:M27) -> 0.809 | ... Q28: =AVERAGE(Q25:Q27) -> 154 | S28: =AVERAGE(S25:S27) -> 0.742 | T28: =AVERAGE(T25:T27) -> 0.71033333 | U28: =AVERAGE(U25:U27) -> 0.641 | V28: =AVERAGE(V25:V27) -> 0.705 | W28: =AVERAGE(W25:W27) -> 0.70133333 | X28: =AVERAGE(X25:X27) -> 0.292 | Y28: =AVERAGE(Y25:Y27) -> 0.817 | Z28: =AVERAGE(Z25:Z27) -> 0.77866667 | ... AD28: =AVERAGE(AD25:AD27) -> 153.33333
B29: standard deviation | F29: =STDEV(F25:F27) -> 0.033501244 | G29: =STDEV(G25:G27) -> 0.0049328829 | H29: =STDEV(H25:H27) -> 0.040377386 | I29: =STDEV(I25:I27) -> 0.012288206 | J29: =STDEV(J25:J27) -> 0.021126603 | K29: =STDEV(K25:K27) -> 0.051419841 | L29: =STDEV(L25:L27) -> 0.058557664 | M29: =STDEV(M25:M27) -> 0.037722672 | ... Q29: =STDEV(Q25:Q27) -> 11 | S29: =STDEV(S25:S27) -> 0.030265492 | T29: =STDEV(T25:T27) -> 0.023713569 | U29: =STDEV(U25:U27) -> 0.031749016 | V29: =STDEV(V25:V27) -> 0.024979992 | W29: =STDEV(W25:W27) -> 0.026102363 | X29: =STDEV(X25:X27) -> 0.063694584 | Y29: =STDEV(Y25:Y27) -> 0.013527749 | Z29: =STDEV(Z25:Z27) -> 0.017387735 | ... AD29: =STDEV(AD25:AD27) -> 2.5166115
A30: TabTransformer + FetalCLIP | B30: 336 | C30: TRUE | D30: all (abdomen, femur, head) | E30: cv1 | F30: 0.786 | G30: 0.781 | H30: 0.702 | I30: 0.77 | J30: 0.772 | K30: 0.45 | L30: 0.904 | M30: 0.806 | N30: 41 | O30: 41 | P30: 18 | Q30: 170 | S30: 0.77 | T30: 0.73 | U30: 0.716 | V30: 0.737 | W30: 0.753 | X30: 0.41 | Y30: 0.75 | Z30: 0.844 | AA30: 56 | AB30: 26 | AC30: 47 | AD30: 141
C31: TRUE | D31: all (abdomen, femur, head) | E31: cv2 | F31: 0.741 | G31: 0.766 | H31: 0.653 | I31: 0.74 | J31: 0.757 | K31: 0.387 | L31: 0.936 | M31: 0.775 | N31: 30 | O31: 51 | P31: 12 | Q31: 176 | S31: 0.729 | T31: 0.68 | U31: 0.641 | V31: 0.686 | W31: 0.694 | X31: 0.273 | Y31: 0.739 | Z31: 0.79 | AA31: 44 | AB31: 37 | AC31: 49 | AD31: 139
C32: TRUE | D32: all (abdomen, femur, head) | E32: cv3 | F32: 0.806 | G32: 0.714 | H32: 0.585 | I32: 0.675 | J32: 0.685 | K32: 0.228 | L32: 0.914 | M32: 0.737 | N32: 21 | O32: 61 | P32: 16 | Q32: 171 | S32: 0.762 | T32: 0.721 | U32: 0.645 | V32: 0.713 | W32: 0.709 | X32: 0.31 | Y32: 0.84 | Z32: 0.777 | AA32: 37 | AB32: 45 | AC32: 30 | AD32: 157
B33: average | F33: =AVERAGE(F30:F32) -> 0.77766667 | G33: =AVERAGE(G30:G32) -> 0.75366667 | H33: =AVERAGE(H30:H32) -> 0.64666667 | I33: =AVERAGE(I30:I32) -> 0.72833333 | J33: =AVERAGE(J30:J32) -> 0.738 | K33: =AVERAGE(K30:K32) -> 0.355 | L33: =AVERAGE(L30:L32) -> 0.918 | M33: =AVERAGE(M30:M32) -> 0.77266667 | ... Q33: =AVERAGE(Q30:Q32) -> 172.33333 | S33: =AVERAGE(S30:S32) -> 0.75366667 | T33: =AVERAGE(T30:T32) -> 0.71033333 | U33: =AVERAGE(U30:U32) -> 0.66733333 | V33: =AVERAGE(V30:V32) -> 0.712 | W33: =AVERAGE(W30:W32) -> 0.71866667 | X33: =AVERAGE(X30:X32) -> 0.331 | Y33: =AVERAGE(Y30:Y32) -> 0.77633333 | Z33: =AVERAGE(Z30:Z32) -> 0.80366667 | ... AD33: =AVERAGE(AD30:AD32) -> 145.66667
B34: standard deviation | F34: =STDEV(F30:F32) -> 0.033291641 | G34: =STDEV(G30:G32) -> 0.035161532 | H34: =STDEV(H30:H32) -> 0.05875656 | I34: =STDEV(I30:I32) -> 0.048562674 | J34: =STDEV(J30:J32) -> 0.046508064 | K34: =STDEV(K30:K32) -> 0.11440717 | L34: =STDEV(L30:L32) -> 0.016370706 | M34: =STDEV(M30:M32) -> 0.034559128 | ... Q34: =STDEV(Q30:Q32) -> 3.2145503 | S34: =STDEV(S30:S32) -> 0.021733231 | T34: =STDEV(T30:T32) -> 0.026652079 | U34: =STDEV(U30:U32) -> 0.042193996 | V34: =STDEV(V30:V32) -> 0.025514702 | W34: =STDEV(W30:W32) -> 0.030664855 | X34: =STDEV(X30:X32) -> 0.070873126 | Y34: =STDEV(Y30:Y32) -> 0.055410589 | Z34: =STDEV(Z30:Z32) -> 0.035529331 | ... AD34: =STDEV(AD30:AD32) -> 9.8657657
